Workbook

Sheet BancoAjustado
A1: Seção | B1: Divisão | C1: Grupo | D1: Classe | E1: Subclasse | F1: Seção | G1: Divisão | H1: Grupo | I1: Classe | J1: Subclasse | K1: Subclasse | L1: e_obj4 | M1: com_agr | N1: com_min
A2: A | B2: 01 | C2: 011 | D2: 01113 | E2: 0111301 | F2: =VLOOKUP(A2,Base!$A:$F,6,FALSE) -> AGRICULTURA, PECUÁRIA, PRODUÇÃO FLORESTAL, PESCA E AQUICULTURA | G2: =VLOOKUP(B2,Base!$B:$F,5,FALSE) -> AGRICULTURA, PECUÁRIA E SERVIÇOS RELACIONADOS | H2: =VLOOKUP(C2,Base!$C:$F,4,FALSE) -> Produção de lavouras temporárias | I2: =VLOOKUP(D2,Base!$D:$F,3,FALSE) -> Cultivo de cereais | J2: =VLOOKUP(E2,Base!$E:$F,2,FALSE) -> Cultivo de arroz | K2: 0111301 | L2: =IFERROR(VLOOKUP($K2,Base_Atividades!$E$1:$N$2398,MATCH(BancoAjustado!L$1,Base_Atividades!$E$1:$N$1,0),FALSE),0) -> 1 | M2: =IFERROR(VLOOKUP($K2,Base_Atividades!$E$1:$N$2398,MATCH(BancoAjustado!M$1,Base_Atividades!$E$1:$N$1,0),FALSE),0) -> 0 | N2: =IFERROR(VLOOKUP($K2,Base_Atividades!$E$1:$N$2398,MATCH(BancoAjustado!N$1,Base_Atividades!$E$1:$N$1,0),FALSE),0) -> 0
A3: A | B3: 01 | C3: 011 | D3: 01113 | E3: 0111302 | F3: =VLOOKUP(A3,Base!$A:$F,6,FALSE) -> AGRICULTURA, PECUÁRIA, PRODUÇÃO FLORESTAL, PESCA E AQUICULTURA | G3: =VLOOKUP(B3,Base!$B:$F,5,FALSE) -> AGRICULTURA, PECUÁRIA E SERVIÇOS RELACIONADOS | H3: =VLOOKUP(C3,Base!$C:$F,4,FALSE) -> Produção de lavouras temporárias | I3: =VLOOKUP(D3,Base!$D:$F,3,FALSE) -> Cultivo de cereais | J3: =VLOOKUP(E3,Base!$E:$F,2,FALSE) -> Cultivo de milho | K3: 0111302 | L3: =IFERROR(VLOOKUP($K3,Base_Atividades!$E$1:$N$2398,MATCH(BancoAjustado!L$1,Base_Atividades!$E$1:$N$1,0),FALSE),0) -> 0 | M3: =IFERROR(VLOOKUP($K3,Base_Atividades!$E$1:$N$2398,MATCH(BancoAjustado!M$1,Base_Atividades!$E$1:$N$1,0),FALSE),0) -> 1 | N3: =IFERROR(VLOOKUP($K3,Base_Atividades!$E$1:$N$2398,MATCH(BancoAjustado!N$1,Base_Atividades!$E$1:$N$1,0),FALSE),0) -> 0
A4: A | B4: 01 | C4: 011 | D4: 01113 | E4: 0111303 | F4: =VLOOKUP(A4,Base!$A:$F,6,FALSE) -> AGRICULTURA, PECUÁRIA, PRODUÇÃO FLORESTAL, PESCA E AQUICULTURA | G4: =VLOOKUP(B4,Base!$B:$F,5,FALSE) -> AGRICULTURA, PECUÁRIA E SERVIÇOS RELACIONADOS | H4: =VLOOKUP(C4,Base!$C:$F,4,FALSE) -> Produção de lavouras temporárias | I4: =VLOOKUP(D4,Base!$D:$F,3,FALSE) -> Cultivo de cereais | J4: =VLOOKUP(E4,Base!$E:$F,2,FALSE) -> Cultivo de trigo | K4: 0111303 | L4: =IFERROR(VLOOKUP($K4,Base_Atividades!$E$1:$N$2398,MATCH(BancoAjustado!L$1,Base_Atividades!$E$1:$N$1,0),FALSE),0) -> 0 | M4: =IFERROR(VLOOKUP($K4,Base_Atividades!$E$1:$N$2398,MATCH(BancoAjustado!M$1,Base_Atividades!$E$1:$N$1,0),FALSE),0) -> 1 | N4: =IFERROR(VLOOKUP($K4,Base_Atividades!$E$1:$N$2398,MATCH(BancoAjustado!N$1,Base_Atividades!$E$1:$N$1,0),FALSE),0) -> 0
A5: A | B5: 01 | C5: 011 | D5: 01113 | E5: 0111399 | F5: =VLOOKUP(A5,Base!$A:$F,6,FALSE) -> AGRICULTURA, PECUÁRIA, PRODUÇÃO FLORESTAL, PESCA E AQUICULTURA | G5: =VLOOKUP(B5,Base!$B:$F,5,FALSE) -> AGRICULTURA, PECUÁRIA E SERVIÇOS RELACIONADOS | H5: =VLOOKUP(C5,Base!$C:$F,4,FALSE) -> Produção de lavouras temporárias | I5: =VLOOKUP(D5,Base!$D:$F,3,FALSE) -> Cultivo de cereais | J5: =VLOOKUP(E5,Base!$E:$F,2,FALSE) -> Cultivo de outros cereais não especificados anteriormente | K5: 0111399 | L5: =IFERROR(VLOOKUP($K5,Base_Atividades!$E$1:$N$2398,MATCH(BancoAjustado!L$1,Base_Atividades!$E$1:$N$1,0),FALSE),0) -> 1 | M5: =IFERROR(VLOOKUP($K5,Base_Atividades!$E$1:$N$2398,MATCH(BancoAjustado!M$1,Base_Atividades!$E$1:$N$1,0),FALSE),0) -> 0 | N5: =IFERROR(VLOOKUP($K5,Base_Atividades!$E$1:$N$2398,MATCH(BancoAjustado!N$1,Base_Atividades!$E$1:$N$1,0),FALSE),0) -> 0
A6: A | B6: 01 | C6: 011 | D6: 01121 | E6: 0112101 | F6: =VLOOKUP(A6,Base!$A:$F,6,FALSE) -> AGRICULTURA, PECUÁRIA, PRODUÇÃO FLORESTAL, PESCA E AQUICULTURA | G6: =VLOOKUP(B6,Base!$B:$F,5,FALSE) -> AGRICULTURA, PECUÁRIA E SERVIÇOS RELACIONADOS | H6: =VLOOKUP(C6,Base!$C:$F,4,FALSE) -> Produção de lavouras temporárias | I6: =VLOOKUP(D6,Base!$D:$F,3,FALSE) -> Cultivo de algodão herbáceo e de outras fibras de lavoura temporária | J6: =VLOOKUP(E6,Base!$E:$F,2,FALSE) -> Cultivo de algodão herbáceo | K6: 0112101 | L6: =IFERROR(VLOOKUP($K6,Base_Atividades!$E$1:$N$2398,MATCH(BancoAjustado!L$1,Base_Atividades!$E$1:$N$1,0),FALSE),0) -> 0 | M6: =IFERROR(VLOOKUP($K6,Base_Atividades!$E$1:$N$2398,MATCH(BancoAjustado!M$1,Base_Atividades!$E$1:$N$1,0),FALSE),0) -> 1 | N6: =IFERROR(VLOOKUP($K6,Base_Atividades!$E$1:$N$2398,MATCH(BancoAjustado!N$1,Base_Atividades!$E$1:$N$1,0),FALSE),0) -> 0
A7: A | B7: 01 | C7: 011 | D7: 01121 | E7: 0112102 | F7: =VLOOKUP(A7,Base!$A:$F,6,FALSE) -> AGRICULTURA, PECUÁRIA, PRODUÇÃO FLORESTAL, PESCA E AQUICULTURA | G7: =VLOOKUP(B7,Base!$B:$F,5,FALSE) -> AGRICULTURA, PECUÁRIA E SERVIÇOS RELACIONADOS | H7: =VLOOKUP(C7,Base!$C:$F,4,FALSE) -> Produção de lavouras temporárias | I7: =VLOOKUP(D7,Base!$D:$F,3,FALSE) -> Cultivo de algodão herbáceo e de outras fibras de lavoura temporária | J7: =VLOOKUP(E7,Base!$E:$F,2,FALSE) -> Cultivo de juta | K7: 0112102 | L7: =IFERROR(VLOOKUP($K7,Base_Atividades!$E$1:$N$2398,MATCH(BancoAjustado!L$1,Base_Atividades!$E$1:$N$1,0),FALSE),0) -> 1 | M7: =IFERROR(VLOOKUP($K7,Base_Atividades!$E$1:$N$2398,MATCH(BancoAjustado!M$1,Base_Atividades!$E$1:$N$1,0),FALSE),0) -> 0 | N7: =IFERROR(VLOOKUP($K7,Base_Atividades!$E$1:$N$2398,MATCH(BancoAjustado!N$1,Base_Atividades!$E$1:$N$1,0),FALSE),0) -> 0
A8: A | B8: 01 | C8: 011 | D8: 01121 | E8: 0112199 | F8: =VLOOKUP(A8,Base!$A:$F,6,FALSE) -> AGRICULTURA, PECUÁRIA, PRODUÇÃO FLORESTAL, PESCA E AQUICULTURA | G8: =VLOOKUP(B8,Base!$B:$F,5,FALSE) -> AGRICULTURA, PECUÁRIA E SERVIÇOS RELACIONADOS | H8: =VLOOKUP(C8,Base!$C:$F,4,FALSE) -> Produção de lavouras temporárias | I8: =VLOOKUP(D8,Base!$D:$F,3,FALSE) -> Cultivo de algodão herbáceo e de outras fibras de lavoura temporária | J8: =VLOOKUP(E8,Base!$E:$F,2,FALSE) -> Cultivo de outras fibras de lavoura temporária não especificadas anteriormente | K8: 0112199 | L8: =IFERROR(VLOOKUP($K8,Base_Atividades!$E$1:$N$2398,MATCH(BancoAjustado!L$1,Base_Atividades!$E$1:$N$1,0),FALSE),0) -> 1 | M8: =IFERROR(VLOOKUP($K8,Base_Atividades!$E$1:$N$2398,MATCH(BancoAjustado!M$1,Base_Atividades!$E$1:$N$1,0),FALSE),0) -> 0 | N8: =IFERROR(VLOOKUP($K8,Base_Atividades!$E$1:$N$2398,MATCH(BancoAjustado!N$1,Base_Atividades!$E$1:$N$1,0),FALSE),0) -> 0
A9: A | B9: 01 | C9: 011 | D9: 01130 | E9: 0113000 | F9: =VLOOKUP(A9,Base!$A:$F,6,FALSE) -> AGRICULTURA, PECUÁRIA, PRODUÇÃO FLORESTAL, PESCA E AQUICULTURA | G9: =VLOOKUP(B9,Base!$B:$F,5,FALSE) -> AGRICULTURA, PECUÁRIA E SERVIÇOS RELACIONADOS | H9: =VLOOKUP(C9,Base!$C:$F,4,FALSE) -> Produção de lavouras temporárias | I9: =VLOOKUP(D9,Base!$D:$F,3,FALSE) -> Cultivo de cana-de-açúcar | J9: =VLOOKUP(E9,Base!$E:$F,2,FALSE) -> Cultivo de cana-de-açúcar | K9: 0113000 | L9: =IFERROR(VLOOKUP($K9,Base_Atividades!$E$1:$N$2398,MATCH(BancoAjustado!L$1,Base_Atividades!$E$1:$N$1,0),FALSE),0) -> 0 | M9: =IFERROR(VLOOKUP($K9,Base_Atividades!$E$1:$N$2398,MATCH(BancoAjustado!M$1,Base_Atividades!$E$1:$N$1,0),FALSE),0) -> 1 | N9: =IFERROR(VLOOKUP($K9,Base_Atividades!$E$1:$N$2398,MATCH(BancoAjustado!N$1,Base_Atividades!$E$1:$N$1,0),FALSE),0) -> 0
A10: A | B10: 01 | C10: 011 | D10: 01148 | E10: 0114800 | F10: =VLOOKUP(A10,Base!$A:$F,6,FALSE) -> AGRICULTURA, PECUÁRIA, PRODUÇÃO FLORESTAL, PESCA E AQUICULTURA | G10: =VLOOKUP(B10,Base!$B:$F,5,FALSE) -> AGRICULTURA, PECUÁRIA E SERVIÇOS RELACIONADOS | H10: =VLOOKUP(C10,Base!$C:$F,4,FALSE) -> Produção de lavouras temporárias | I10: =VLOOKUP(D10,Base!$D:$F,3,FALSE) -> Cultivo de fumo | J10: =VLOOKUP(E10,Base!$E:$F,2,FALSE) -> Cultivo de fumo | K10: 0114800 | L10: =IFERROR(VLOOKUP($K10,Base_Atividades!$E$1:$N$2398,MATCH(BancoAjustado!L$1,Base_Atividades!$E$1:$N$1,0),FALSE),0) -> 0 | M10: =IFERROR(VLOOKUP($K10,Base_Atividades!$E$1:$N$2398,MATCH(BancoAjustado!M$1,Base_Atividades!$E$1:$N$1,0),FALSE),0) -> 0 | N10: =IFERROR(VLOOKUP($K10,Base_Atividades!$E$1:$N$2398,MATCH(BancoAjustado!N$1,Base_Atividades!$E$1:$N$1,0),FALSE),0) -> 0
A11: A | B11: 01 | C11: 011 | D11: 01156 | E11: 0115600 | F11: =VLOOKUP(A11,Base!$A:$F,6,FALSE) -> AGRICULTURA, PECUÁRIA, PRODUÇÃO FLORESTAL, PESCA E AQUICULTURA | G11: =VLOOKUP(B11,Base!$B:$F,5,FALSE) -> AGRICULTURA, PECUÁRIA E SERVIÇOS RELACIONADOS | H11: =VLOOKUP(C11,Base!$C:$F,4,FALSE) -> Produção de lavouras temporárias | I11: =VLOOKUP(D11,Base!$D:$F,3,FALSE) -> Cultivo de soja | J11: =VLOOKUP(E11,Base!$E:$F,2,FALSE) -> Cultivo de soja | K11: 0115600 | L11: =IFERROR(VLOOKUP($K11,Base_Atividades!$E$1:$N$2398,MATCH(BancoAjustado!L$1,Base_Atividades!$E$1:$N$1,0),FALSE),0) -> 0 | M11: =IFERROR(VLOOKUP($K11,Base_Atividades!$E$1:$N$2398,MATCH(BancoAjustado!M$1,Base_Atividades!$E$1:$N$1,0),FALSE),0) -> 1 | N11: =IFERROR(VLOOKUP($K11,Base_Atividades!$E$1:$N$2398,MATCH(BancoAjustado!N$1,Base_Atividades!$E$1:$N$1,0),FALSE),0) -> 0
A12: A | B12: 01 | C12: 011 | D12: 01164 | E12: 0116401 | F12: =VLOOKUP(A12,Base!$A:$F,6,FALSE) -> AGRICULTURA, PECUÁRIA, PRODUÇÃO FLORESTAL, PESCA E AQUICULTURA | G12: =VLOOKUP(B12,Base!$B:$F,5,FALSE) -> AGRICULTURA, PECUÁRIA E SERVIÇOS RELACIONADOS | H12: =VLOOKUP(C12,Base!$C:$F,4,FALSE) -> Produção de lavouras temporárias | I12: =VLOOKUP(D12,Base!$D:$F,3,FALSE) -> Cultivo de oleaginosas de lavoura temporária, exceto soja | J12: =VLOOKUP(E12,Base!$E:$F,2,FALSE) -> Cultivo de amendoim | K12: 0116401 | L12: =IFERROR(VLOOKUP($K12,Base_Atividades!$E$1:$N$2398,MATCH(BancoAjustado!L$1,Base_Atividades!$E$1:$N$1,0),FALSE),0) -> 1 | M12: =IFERROR(VLOOKUP($K12,Base_Atividades!$E$1:$N$2398,MATCH(BancoAjustado!M$1,Base_Atividades!$E$1:$N$1,0),FALSE),0) -> 0 | N12: =IFERROR(VLOOKUP($K12,Base_Atividades!$E$1:$N$2398,MATCH(BancoAjustado!N$1,Base_Atividades!$E$1:$N$1,0),FALSE),0) -> 0
A13: A | B13: 01 | C13: 011 | D13: 01164 | E13: 0116402 | F13: =VLOOKUP(A13,Base!$A:$F,6,FALSE) -> AGRICULTURA, PECUÁRIA, PRODUÇÃO FLORESTAL, PESCA E AQUICULTURA | G13: =VLOOKUP(B13,Base!$B:$F,5,FALSE) -> AGRICULTURA, PECUÁRIA E SERVIÇOS RELACIONADOS | H13: =VLOOKUP(C13,Base!$C:$F,4,FALSE) -> Produção de lavouras temporárias | I13: =VLOOKUP(D13,Base!$D:$F,3,FALSE) -> Cultivo de oleaginosas de lavoura temporária, exceto soja | J13: =VLOOKUP(E13,Base!$E:$F,2,FALSE) -> Cultivo de girassol | K13: 0116402 | L13: =IFERROR(VLOOKUP($K13,Base_Atividades!$E$1:$N$2398,MATCH(BancoAjustado!L$1,Base_Atividades!$E$1:$N$1,0),FALSE),0) -> 1 | M13: =IFERROR(VLOOKUP($K13,Base_Atividades!$E$1:$N$2398,MATCH(BancoAjustado!M$1,Base_Atividades!$E$1:$N$1,0),FALSE),0) -> 0 | N13: =IFERROR(VLOOKUP($K13,Base_Atividades!$E$1:$N$2398,MATCH(BancoAjustado!N$1,Base_Atividades!$E$1:$N$1,0),FALSE),0) -> 0
... A346: C | B346: 20 | C346: 209 | D346: 20991 | E346: 2099199 | F346: =VLOOKUP(A346,Base!$A:$F,6,FALSE) -> INDÚSTRIAS DE TRANSFORMAÇÃO | G346: =VLOOKUP(B346,Base!$B:$F,5,FALSE) -> FABRICAÇÃO DE PRODUTOS QUÍMICOS | H346: =VLOOKUP(C346,Base!$C:$F,4,FALSE) -> Fabricação de produtos e preparados químicos diversos | I346: =VLOOKUP(D346,Base!$D:$F,3,FALSE) -> Fabricação de produtos químicos não especificados anteriormente | J346: =VLOOKUP(E346,Base!$E:$F,2,FALSE) -> Fabricação de outros produtos químicos não especificados anteriormente | K346: 2099199 | L346: =IFERROR(VLOOKUP($K346,Base_Atividades!$E$1:$N$2398,MATCH(BancoAjustado!L$1,Base_Atividades!$E$1:$N$1,0),FALSE),0) -> 1 | M346: =IFERROR(VLOOKUP($K346,Base_Atividades!$E$1:$N$2398,MATCH(BancoAjustado!M$1,Base_Atividades!$E$1:$N$1,0),FALSE),0) -> 0 | N346: =IFERROR(VLOOKUP($K346,Base_Atividades!$E$1:$N$2398,MATCH(BancoAjustado!N$1,Base_Atividades!$E$1:$N$1,0),FALSE),0) -> 0
A347: C | B347: 21 | C347: 211 | D347: 21106 | E347: 2110600 | F347: =VLOOKUP(A347,Base!$A:$F,6,FALSE) -> INDÚSTRIAS DE TRANSFORMAÇÃO | G347: =VLOOKUP(B347,Base!$B:$F,5,FALSE) -> FABRICAÇÃO DE PRODUTOS FARMOQUÍMICOS E FARMACÊUTICOS | H347: =VLOOKUP(C347,Base!$C:$F,4,FALSE) -> Fabricação de produtos farmoquímicos | I347: =VLOOKUP(D347,Base!$D:$F,3,FALSE) -> Fabricação de produtos farmoquímicos | J347: =VLOOKUP(E347,Base!$E:$F,2,FALSE) -> Fabricação de produtos farmoquímicos | K347: 2110600 | L347: =IFERROR(VLOOKUP($K347,Base_Atividades!$E$1:$N$2398,MATCH(BancoAjustado!L$1,Base_Atividades!$E$1:$N$1,0),FALSE),0) -> 1 | M347: =IFERROR(VLOOKUP($K347,Base_Atividades!$E$1:$N$2398,MATCH(BancoAjustado!M$1,Base_Atividades!$E$1:$N$1,0),FALSE),0) -> 0 | N347: =IFERROR(VLOOKUP($K347,Base_Atividades!$E$1:$N$2398,MATCH(BancoAjustado!N$1,Base_Atividades!$E$1:$N$1,0),FALSE),0) -> 0
A348: C | B348: 21 | C348: 212 | D348: 21211 | E348: 2121101 | F348: =VLOOKUP(A348,Base!$A:$F,6,FALSE) -> INDÚSTRIAS DE TRANSFORMAÇÃO | G348: =VLOOKUP(B348,Base!$B:$F,5,FALSE) -> FABRICAÇÃO DE PRODUTOS FARMOQUÍMICOS E FARMACÊUTICOS | H348: =VLOOKUP(C348,Base!$C:$F,4,FALSE) -> Fabricação de produtos farmacêuticos | I348: =VLOOKUP(D348,Base!$D:$F,3,FALSE) -> Fabricação de medicamentos para uso humano | J348: =VLOOKUP(E348,Base!$E:$F,2,FALSE) -> Fabricação de medicamentos alopáticos para uso humano | K348: 2121101 | L348: =IFERROR(VLOOKUP($K348,Base_Atividades!$E$1:$N$2398,MATCH(BancoAjustado!L$1,Base_Atividades!$E$1:$N$1,0),FALSE),0) -> 1 | M348: =IFERROR(VLOOKUP($K348,Base_Atividades!$E$1:$N$2398,MATCH(BancoAjustado!M$1,Base_Atividades!$E$1:$N$1,0),FALSE),0) -> 0 | N348: =IFERROR(VLOOKUP($K348,Base_Atividades!$E$1:$N$2398,MATCH(BancoAjustado!N$1,Base_Atividades!$E$1:$N$1,0),FALSE),0) -> 0
A349: C | B349: 21 | C349: 212 | D349: 21211 | E349: 2121102 | F349: =VLOOKUP(A349,Base!$A:$F,6,FALSE) -> INDÚSTRIAS DE TRANSFORMAÇÃO | G349: =VLOOKUP(B349,Base!$B:$F,5,FALSE) -> FABRICAÇÃO DE PRODUTOS FARMOQUÍMICOS E FARMACÊUTICOS | H349: =VLOOKUP(C349,Base!$C:$F,4,FALSE) -> Fabricação de produtos farmacêuticos | I349: =VLOOKUP(D349,Base!$D:$F,3,FALSE) -> Fabricação de medicamentos para uso humano | J349: =VLOOKUP(E349,Base!$E:$F,2,FALSE) -> Fabricação de medicamentos homeopáticos para uso humano | K349: 2121102 | L349: =IFERROR(VLOOKUP($K349,Base_Atividades!$E$1:$N$2398,MATCH(BancoAjustado!L$1,Base_Atividades!$E$1:$N$1,0),FALSE),0) -> 1 | M349: =IFERROR(VLOOKUP($K349,Base_Atividades!$E$1:$N$2398,MATCH(BancoAjustado!M$1,Base_Atividades!$E$1:$N$1,0),FALSE),0) -> 0 | N349: =IFERROR(VLOOKUP($K349,Base_Atividades!$E$1:$N$2398,MATCH(BancoAjustado!N$1,Base_Atividades!$E$1:$N$1,0),FALSE),0) -> 0
A350: C | B350: 21 | C350: 212 | D350: 21211 | E350: 2121103 | F350: =VLOOKUP(A350,Base!$A:$F,6,FALSE) -> INDÚSTRIAS DE TRANSFORMAÇÃO | G350: =VLOOKUP(B350,Base!$B:$F,5,FALSE) -> FABRICAÇÃO DE PRODUTOS FARMOQUÍMICOS E FARMACÊUTICOS | H350: =VLOOKUP(C350,Base!$C:$F,4,FALSE) -> Fabricação de produtos farmacêuticos | I350: =VLOOKUP(D350,Base!$D:$F,3,FALSE) -> Fabricação de medicamentos para uso humano | J350: =VLOOKUP(E350,Base!$E:$F,2,FALSE) -> Fabricação de medicamentos fitoterápicos para uso humano | K350: 2121103 | L350: =IFERROR(VLOOKUP($K350,Base_Atividades!$E$1:$N$2398,MATCH(BancoAjustado!L$1,Base_Atividades!$E$1:$N$1,0),FALSE),0) -> 1 | M350: =IFERROR(VLOOKUP($K350,Base_Atividades!$E$1:$N$2398,MATCH(BancoAjustado!M$1,Base_Atividades!$E$1:$N$1,0),FALSE),0) -> 0 | N350: =IFERROR(VLOOKUP($K350,Base_Atividades!$E$1:$N$2398,MATCH(BancoAjustado!N$1,Base_Atividades!$E$1:$N$1,0),FALSE),0) -> 0
A351: C | B351: 21 | C351: 212 | D351: 21220 | E351: 2122000 | F351: =VLOOKUP(A351,Base!$A:$F,6,FALSE) -> INDÚSTRIAS DE TRANSFORMAÇÃO | G351: =VLOOKUP(B351,Base!$B:$F,5,FALSE) -> FABRICAÇÃO DE PRODUTOS FARMOQUÍMICOS E FARMACÊUTICOS | H351: =VLOOKUP(C351,Base!$C:$F,4,FALSE) -> Fabricação de produtos farmacêuticos | I351: =VLOOKUP(D351,Base!$D:$F,3,FALSE) -> Fabricação de medicamentos para uso veterinário | J351: =VLOOKUP(E351,Base!$E:$F,2,FALSE) -> Fabricação de medicamentos para uso veterinário | K351: 2122000 | L351: =IFERROR(VLOOKUP($K351,Base_Atividades!$E$1:$N$2398,MATCH(BancoAjustado!L$1,Base_Atividades!$E$1:$N$1,0),FALSE),0) -> 1 | M351: =IFERROR(VLOOKUP($K351,Base_Atividades!$E$1:$N$2398,MATCH(BancoAjustado!M$1,Base_Atividades!$E$1:$N$1,0),FALSE),0) -> 0 | N351: =IFERROR(VLOOKUP($K351,Base_Atividades!$E$1:$N$2398,MATCH(BancoAjustado!N$1,Base_Atividades!$E$1:$N$1,0),FALSE),0) -> 0
A352: C | B352: 21 | C352: 212 | D352: 21238 | E352: 2123800 | F352: =VLOOKUP(A352,Base!$A:$F,6,FALSE) -> INDÚSTRIAS DE TRANSFORMAÇÃO | G352: =VLOOKUP(B352,Base!$B:$F,5,FALSE) -> FABRICAÇÃO DE PRODUTOS FARMOQUÍMICOS E FARMACÊUTICOS | H352: =VLOOKUP(C352,Base!$C:$F,4,FALSE) -> Fabricação de produtos farmacêuticos | I352: =VLOOKUP(D352,Base!$D:$F,3,FALSE) -> Fabricação de preparações farmacêuticas | J352: =VLOOKUP(E352,Base!$E:$F,2,FALSE) -> Fabricação de preparações farmacêuticas | K352: 2123800 | L352: =IFERROR(VLOOKUP($K352,Base_Atividades!$E$1:$N$2398,MATCH(BancoAjustado!L$1,Base_Atividades!$E$1:$N$1,0),FALSE),0) -> 1 | M352: =IFERROR(VLOOKUP($K352,Base_Atividades!$E$1:$N$2398,MATCH(BancoAjustado!M$1,Base_Atividades!$E$1:$N$1,0),FALSE),0) -> 0 | N352: =IFERROR(VLOOKUP($K352,Base_Atividades!$E$1:$N$2398,MATCH(BancoAjustado!N$1,Base_Atividades!$E$1:$N$1,0),FALSE),0) -> 0
A353: C | B353: 22 | C353: 221 | D353: 22111 | E353: 2211100 | F353: =VLOOKUP(A353,Base!$A:$F,6,FALSE) -> INDÚSTRIAS DE TRANSFORMAÇÃO | G353: =VLOOKUP(B353,Base!$B:$F,5,FALSE) -> FABRICAÇÃO DE PRODUTOS DE BORRACHA E DE MATERIAL PLÁSTICO | H353: =VLOOKUP(C353,Base!$C:$F,4,FALSE) -> Fabricação de produtos de borracha | I353: =VLOOKUP(D353,Base!$D:$F,3,FALSE) -> Fabricação de pneumáticos e de câmaras-de-ar | J353: =VLOOKUP(E353,Base!$E:$F,2,FALSE) -> Fabricação de pneumáticos e de câmaras-de-ar | K353: 2211100 | L353: =IFERROR(VLOOKUP($K353,Base_Atividades!$E$1:$N$2398,MATCH(BancoAjustado!L$1,Base_Atividades!$E$1:$N$1,0),FALSE),0) -> 1 | M353: =IFERROR(VLOOKUP($K353,Base_Atividades!$E$1:$N$2398,MATCH(BancoAjustado!M$1,Base_Atividades!$E$1:$N$1,0),FALSE),0) -> 0 | N353: =IFERROR(VLOOKUP($K353,Base_Atividades!$E$1:$N$2398,MATCH(BancoAjustado!N$1,Base_Atividades!$E$1:$N$1,0),FALSE),0) -> 0
A354: C | B354: 22 | C354: 221 | D354: 22129 | E354: 2212900 | F354: =VLOOKUP(A354,Base!$A:$F,6,FALSE) -> INDÚSTRIAS DE TRANSFORMAÇÃO | G354: =VLOOKUP(B354,Base!$B:$F,5,FALSE) -> FABRICAÇÃO DE PRODUTOS DE BORRACHA E DE MATERIAL PLÁSTICO | H354: =VLOOKUP(C354,Base!$C:$F,4,FALSE) -> Fabricação de produtos de borracha | I354: =VLOOKUP(D354,Base!$D:$F,3,FALSE) -> Reforma de pneumáticos usados | J354: =VLOOKUP(E354,Base!$E:$F,2,FALSE) -> Reforma de pneumáticos usados | K354: 2212900 | L354: =IFERROR(VLOOKUP($K354,Base_Atividades!$E$1:$N$2398,MATCH(BancoAjustado!L$1,Base_Atividades!$E$1:$N$1,0),FALSE),0) -> 1 | M354: =IFERROR(VLOOKUP($K354,Base_Atividades!$E$1:$N$2398,MATCH(BancoAjustado!M$1,Base_Atividades!$E$1:$N$1,0),FALSE),0) -> 0 | N354: =IFERROR(VLOOKUP($K354,Base_Atividades!$E$1:$N$2398,MATCH(BancoAjustado!N$1,Base_Atividades!$E$1:$N$1,0),FALSE),0) -> 0
A355: C | B355: 22 | C355: 221 | D355: 22196 | E355: 2219600 | F355: =VLOOKUP(A355,Base!$A:$F,6,FALSE) -> INDÚSTRIAS DE TRANSFORMAÇÃO | G355: =VLOOKUP(B355,Base!$B:$F,5,FALSE) -> FABRICAÇÃO DE PRODUTOS DE BORRACHA E DE MATERIAL PLÁSTICO | H355: =VLOOKUP(C355,Base!$C:$F,4,FALSE) -> Fabricação de produtos de borracha | I355: =VLOOKUP(D355,Base!$D:$F,3,FALSE) -> Fabricação de artefatos de borracha não especificados anteriormente | J355: =VLOOKUP(E355,Base!$E:$F,2,FALSE) -> Fabricação de artefatos de borracha não especificados anteriormente | K355: 2219600 | L355: =IFERROR(VLOOKUP($K355,Base_Atividades!$E$1:$N$2398,MATCH(BancoAjustado!L$1,Base_Atividades!$E$1:$N$1,0),FALSE),0) -> 1 | M355: =IFERROR(VLOOKUP($K355,Base_Atividades!$E$1:$N$2398,MATCH(BancoAjustado!M$1,Base_Atividades!$E$1:$N$1,0),FALSE),0) -> 0 | N355: =IFERROR(VLOOKUP($K355,Base_Atividades!$E$1:$N$2398,MATCH(BancoAjustado!N$1,Base_Atividades!$E$1:$N$1,0),FALSE),0) -> 0
A356: C | B356: 22 | C356: 222 | D356: 22218 | E356: 2221800 | F356: =VLOOKUP(A356,Base!$A:$F,6,FALSE) -> INDÚSTRIAS DE TRANSFORMAÇÃO | G356: =VLOOKUP(B356,Base!$B:$F,5,FALSE) -> FABRICAÇÃO DE PRODUTOS DE BORRACHA E DE MATERIAL PLÁSTICO | H356: =VLOOKUP(C356,Base!$C:$F,4,FALSE) -> Fabricação de produtos de material plástico | I356: =VLOOKUP(D356,Base!$D:$F,3,FALSE) -> Fabricação de laminados planos e tubulares de material plástico | J356: =VLOOKUP(E356,Base!$E:$F,2,FALSE) -> Fabricação de laminados planos e tubulares de material plástico | K356: 2221800 | L356: =IFERROR(VLOOKUP($K356,Base_Atividades!$E$1:$N$2398,MATCH(BancoAjustado!L$1,Base_Atividades!$E$1:$N$1,0),FALSE),0) -> 1 | M356: =IFERROR(VLOOKUP($K356,Base_Atividades!$E$1:$N$2398,MATCH(BancoAjustado!M$1,Base_Atividades!$E$1:$N$1,0),FALSE),0) -> 0 | N356: =IFERROR(VLOOKUP($K356,Base_Atividades!$E$1:$N$2398,MATCH(BancoAjustado!N$1,Base_Atividades!$E$1:$N$1,0),FALSE),0) -> 0
A357: C | B357: 22 | C357: 222 | D357: 22226 | E357: 2222600 | F357: =VLOOKUP(A357,Base!$A:$F,6,FALSE) -> INDÚSTRIAS DE TRANSFORMAÇÃO | G357: =VLOOKUP(B357,Base!$B:$F,5,FALSE) -> FABRICAÇÃO DE PRODUTOS DE BORRACHA E DE MATERIAL PLÁSTICO | H357: =VLOOKUP(C357,Base!$C:$F,4,FALSE) -> Fabricação de produtos de material plástico | I357: =VLOOKUP(D357,Base!$D:$F,3,FALSE) -> Fabricação de embalagens de material plástico | J357: =VLOOKUP(E357,Base!$E:$F,2,FALSE) -> Fabricação de embalagens de material plástico | K357: 2222600 | L357: =IFERROR(VLOOKUP($K357,Base_Atividades!$E$1:$N$2398,MATCH(BancoAjustado!L$1,Base_Atividades!$E$1:$N$1,0),FALSE),0) -> 1 | M357: =IFERROR(VLOOKUP($K357,Base_Atividades!$E$1:$N$2398,MATCH(BancoAjustado!M$1,Base_Atividades!$E$1:$N$1,0),FALSE),0) -> 0 | N357: =IFERROR(VLOOKUP($K357,Base_Atividades!$E$1:$N$2398,MATCH(BancoAjustado!N$1,Base_Atividades!$E$1:$N$1,0),FALSE),0) -> 0
A358: C | B358: 22 | C358: 222 | D358: 22234 | E358: 2223400 | F358: =VLOOKUP(A358,Base!$A:$F,6,FALSE) -> INDÚSTRIAS DE TRANSFORMAÇÃO | G358: =VLOOKUP(B358,Base!$B:$F,5,FALSE) -> FABRICAÇÃO DE PRODUTOS DE BORRACHA E DE MATERIAL PLÁSTICO | H358: =VLOOKUP(C358,Base!$C:$F,4,FALSE) -> Fabricação de produtos de material plástico | I358: =VLOOKUP(D358,Base!$D:$F,3,FALSE) -> Fabricação de tubos e acessórios de material plástico para uso na construção | J358: =VLOOKUP(E358,Base!$E:$F,2,FALSE) -> Fabricação de tubos e acessórios de material plástico para uso na construção | K358: 2223400 | L358: =IFERROR(VLOOKUP($K358,Base_Atividades!$E$1:$N$2398,MATCH(BancoAjustado!L$1,Base_Atividades!$E$1:$N$1,0),FALSE),0) -> 1 | M358: =IFERROR(VLOOKUP($K358,Base_Atividades!$E$1:$N$2398,MATCH(BancoAjustado!M$1,Base_Atividades!$E$1:$N$1,0),FALSE),0) -> 0 | N358: =IFERROR(VLOOKUP($K358,Base_Atividades!$E$1:$N$2398,MATCH(BancoAjustado!N$1,Base_Atividades!$E$1:$N$1,0),FALSE),0) -> 0
A359: C | B359: 22 | C359: 222 | D359: 22293 | E359: 2229301 | F359: =VLOOKUP(A359,Base!$A:$F,6,FALSE) -> INDÚSTRIAS DE TRANSFORMAÇÃO | G359: =VLOOKUP(B359,Base!$B:$F,5,FALSE) -> FABRICAÇÃO DE PRODUTOS DE BORRACHA E DE MATERIAL PLÁSTICO | H359: =VLOOKUP(C359,Base!$C:$F,4,FALSE) -> Fabricação de produtos de material plástico | I359: =VLOOKUP(D359,Base!$D:$F,3,FALSE) -> Fabricação de artefatos de material plástico não especificados anteriormente | J359: =VLOOKUP(E359,Base!$E:$F,2,FALSE) -> Fabricação de artefatos de material plástico para uso pessoal e doméstico | K359: 2229301 | L359: =IFERROR(VLOOKUP($K359,Base_Atividades!$E$1:$N$2398,MATCH(BancoAjustado!L$1,Base_Atividades!$E$1:$N$1,0),FALSE),0) -> 1 | M359: =IFERROR(VLOOKUP($K359,Base_Atividades!$E$1:$N$2398,MATCH(BancoAjustado!M$1,Base_Atividades!$E$1:$N$1,0),FALSE),0) -> 0 | N359: =IFERROR(VLOOKUP($K359,Base_Atividades!$E$1:$N$2398,MATCH(BancoAjustado!N$1,Base_Atividades!$E$1:$N$1,0),FALSE),0) -> 0
A360: C | B360: 22 | C360: 222 | D360: 22293 | E360: 2229302 | F360: =VLOOKUP(A360,Base!$A:$F,6,FALSE) -> INDÚSTRIAS DE TRANSFORMAÇÃO | G360: =VLOOKUP(B360,Base!$B:$F,5,FALSE) -> FABRICAÇÃO DE PRODUTOS DE BORRACHA E DE MATERIAL PLÁSTICO | H360: =VLOOKUP(C360,Base!$C:$F,4,FALSE) -> Fabricação de produtos de material plástico | I360: =VLOOKUP(D360,Base!$D:$F,3,FALSE) -> Fabricação de artefatos de material plástico não especificados anteriormente | J360: =VLOOKUP(E360,Base!$E:$F,2,FALSE) -> Fabricação de artefatos de material plástico para usos industriais | K360: 2229302 | L360: =IFERROR(VLOOKUP($K360,Base_Atividades!$E$1:$N$2398,MATCH(BancoAjustado!L$1,Base_Atividades!$E$1:$N$1,0),FALSE),0) -> 1 | M360: =IFERROR(VLOOKUP($K360,Base_Atividades!$E$1:$N$2398,MATCH(BancoAjustado!M$1,Base_Atividades!$E$1:$N$1,0),FALSE),0) -> 0 | N360: =IFERROR(VLOOKUP($K360,Base_Atividades!$E$1:$N$2398,MATCH(BancoAjustado!N$1,Base_Atividades!$E$1:$N$1,0),FALSE),0) -> 0
A361: C | B361: 22 | C361: 222 | D361: 22293 | E361: 2229303 | F361: =VLOOKUP(A361,Base!$A:$F,6,FALSE) -> INDÚSTRIAS DE TRANSFORMAÇÃO | G361: =VLOOKUP(B361,Base!$B:$F,5,FALSE) -> FABRICAÇÃO DE PRODUTOS DE BORRACHA E DE MATERIAL PLÁSTICO | H361: =VLOOKUP(C361,Base!$C:$F,4,FALSE) -> Fabricação de produtos de material plástico | I361: =VLOOKUP(D361,Base!$D:$F,3,FALSE) -> Fabricação de artefatos de material plástico não especificados anteriormente | J361: =VLOOKUP(E361,Base!$E:$F,2,FALSE) -> Fabricação de artefatos de material plástico para uso na construção, exceto tubos e acessórios | K361: 2229303 | L361: =IFERROR(VLOOKUP($K361,Base_Atividades!$E$1:$N$2398,MATCH(BancoAjustado!L$1,Base_Atividades!$E$1:$N$1,0),FALSE),0) -> 1 | M361: =IFERROR(VLOOKUP($K361,Base_Atividades!$E$1:$N$2398,MATCH(BancoAjustado!M$1,Base_Atividades!$E$1:$N$1,0),FALSE),0) -> 0 | N361: =IFERROR(VLOOKUP($K361,Base_Atividades!$E$1:$N$2398,MATCH(BancoAjustado!N$1,Base_Atividades!$E$1:$N$1,0),FALSE),0) -> 0
A362: C | B362: 22 | C362: 222 | D362: 22293 | E362: 2229399 | F362: =VLOOKUP(A362,Base!$A:$F,6,FALSE) -> INDÚSTRIAS DE TRANSFORMAÇÃO | G362: =VLOOKUP(B362,Base!$B:$F,5,FALSE) -> FABRICAÇÃO DE PRODUTOS DE BORRACHA E DE MATERIAL PLÁSTICO | H362: =VLOOKUP(C362,Base!$C:$F,4,FALSE) -> Fabricação de produtos de material plástico | I362: =VLOOKUP(D362,Base!$D:$F,3,FALSE) -> Fabricação de artefatos de material plástico não especificados anteriormente | J362: =VLOOKUP(E362,Base!$E:$F,2,FALSE) -> Fabricação de artefatos de material plástico para outros usos não especificados anteriormente | K362: 2229399 | L362: =IFERROR(VLOOKUP($K362,Base_Atividades!$E$1:$N$2398,MATCH(BancoAjustado!L$1,Base_Atividades!$E$1:$N$1,0),FALSE),0) -> 1 | M362: =IFERROR(VLOOKUP($K362,Base_Atividades!$E$1:$N$2398,MATCH(BancoAjustado!M$1,Base_Atividades!$E$1:$N$1,0),FALSE),0) -> 0 | N362: =IFERROR(VLOOKUP($K362,Base_Atividades!$E$1:$N$2398,MATCH(BancoAjustado!N$1,Base_Atividades!$E$1:$N$1,0),FALSE),0) -> 0
A363: C | B363: 23 | C363: 231 | D363: 23117 | E363: 2311700 | F363: =VLOOKUP(A363,Base!$A:$F,6,FALSE) -> INDÚSTRIAS DE TRANSFORMAÇÃO | G363: =VLOOKUP(B363,Base!$B:$F,5,FALSE) -> FABRICAÇÃO DE PRODUTOS DE MINERAIS NÃO METÁLICOS | H363: =VLOOKUP(C363,Base!$C:$F,4,FALSE) -> Fabricação de vidro e de produtos do vidro | I363: =VLOOKUP(D363,Base!$D:$F,3,FALSE) -> Fabricação de vidro plano e de segurança | J363: =VLOOKUP(E363,Base!$E:$F,2,FALSE) -> Fabricação de vidro plano e de segurança | K363: 2311700 | L363: =IFERROR(VLOOKUP($K363,Base_Atividades!$E$1:$N$2398,MATCH(BancoAjustado!L$1,Base_Atividades!$E$1:$N$1,0),FALSE),0) -> 0 | M363: =IFERROR(VLOOKUP($K363,Base_Atividades!$E$1:$N$2398,MATCH(BancoAjustado!M$1,Base_Atividades!$E$1:$N$1,0),FALSE),0) -> 0 | N363: =IFERROR(VLOOKUP($K363,Base_Atividades!$E$1:$N$2398,MATCH(BancoAjustado!N$1,Base_Atividades!$E$1:$N$1,0),FALSE),0) -> 0
A364: C | B364: 23 | C364: 231 | D364: 23125 | E364: 2312500 | F364: =VLOOKUP(A364,Base!$A:$F,6,FALSE) -> INDÚSTRIAS DE TRANSFORMAÇÃO | G364: =VLOOKUP(B364,Base!$B:$F,5,FALSE) -> FABRICAÇÃO DE PRODUTOS DE MINERAIS NÃO METÁLICOS | H364: =VLOOKUP(C364,Base!$C:$F,4,FALSE) -> Fabricação de vidro e de produtos do vidro | I364: =VLOOKUP(D364,Base!$D:$F,3,FALSE) -> Fabricação de embalagens de vidro | J364: =VLOOKUP(E364,Base!$E:$F,2,FALSE) -> Fabricação de embalagens de vidro | K364: 2312500 | L364: =IFERROR(VLOOKUP($K364,Base_Atividades!$E$1:$N$2398,MATCH(BancoAjustado!L$1,Base_Atividades!$E$1:$N$1,0),FALSE),0) -> 0 | M364: =IFERROR(VLOOKUP($K364,Base_Atividades!$E$1:$N$2398,MATCH(BancoAjustado!M$1,Base_Atividades!$E$1:$N$1,0),FALSE),0) -> 0 | N364: =IFERROR(VLOOKUP($K364,Base_Atividades!$E$1:$N$2398,MATCH(BancoAjustado!N$1,Base_Atividades!$E$1:$N$1,0),FALSE),0) -> 0
A365: C | B365: 23 | C365: 231 | D365: 23192 | E365: 2319200 | F365: =VLOOKUP(A365,Base!$A:$F,6,FALSE) -> INDÚSTRIAS DE TRANSFORMAÇÃO | G365: =VLOOKUP(B365,Base!$B:$F,5,FALSE) -> FABRICAÇÃO DE PRODUTOS DE MINERAIS NÃO METÁLICOS | H365: =VLOOKUP(C365,Base!$C:$F,4,FALSE) -> Fabricação de vidro e de produtos do vidro | I365: =VLOOKUP(D365,Base!$D:$F,3,FALSE) -> Fabricação de artigos de vidro | J365: =VLOOKUP(E365,Base!$E:$F,2,FALSE) -> Fabricação de artigos de vidro | K365: 2319200 | L365: =IFERROR(VLOOKUP($K365,Base_Atividades!$E$1:$N$2398,MATCH(BancoAjustado!L$1,Base_Atividades!$E$1:$N$1,0),FALSE),0) -> 0 | M365: =IFERROR(VLOOKUP($K365,Base_Atividades!$E$1:$N$2398,MATCH(BancoAjustado!M$1,Base_Atividades!$E$1:$N$1,0),FALSE),0) -> 0 | N365: =IFERROR(VLOOKUP($K365,Base_Atividades!$E$1:$N$2398,MATCH(BancoAjustado!N$1,Base_Atividades!$E$1:$N$1,0),FALSE),0) -> 0
A366: C | B366: 23 | C366: 232 | D366: 23206 | E366: 2320600 | F366: =VLOOKUP(A366,Base!$A:$F,6,FALSE) -> INDÚSTRIAS DE TRANSFORMAÇÃO | G366: =VLOOKUP(B366,Base!$B:$F,5,FALSE) -> FABRICAÇÃO DE PRODUTOS DE MINERAIS NÃO METÁLICOS | H366: =VLOOKUP(C366,Base!$C:$F,4,FALSE) -> Fabricação de cimento | I366: =VLOOKUP(D366,Base!$D:$F,3,FALSE) -> Fabricação de cimento | J366: =VLOOKUP(E366,Base!$E:$F,2,FALSE) -> Fabricação de cimento | K366: 2320600 | L366: =IFERROR(VLOOKUP($K366,Base_Atividades!$E$1:$N$2398,MATCH(BancoAjustado!L$1,Base_Atividades!$E$1:$N$1,0),FALSE),0) -> 0 | M366: =IFERROR(VLOOKUP($K366,Base_Atividades!$E$1:$N$2398,MATCH(BancoAjustado!M$1,Base_Atividades!$E$1:$N$1,0),FALSE),0) -> 0 | N366: =IFERROR(VLOOKUP($K366,Base_Atividades!$E$1:$N$2398,MATCH(BancoAjustado!N$1,Base_Atividades!$E$1:$N$1,0),FALSE),0) -> 0
A367: C | B367: 23 | C367: 233 | D367: 23303 | E367: 2330301 | F367: =VLOOKUP(A367,Base!$A:$F,6,FALSE) -> INDÚSTRIAS DE TRANSFORMAÇÃO | G367: =VLOOKUP(B367,Base!$B:$F,5,FALSE) -> FABRICAÇÃO DE PRODUTOS DE MINERAIS NÃO METÁLICOS | H367: =VLOOKUP(C367,Base!$C:$F,4,FALSE) -> Fabricação de artefatos de concreto, cimento, fibrocimento, gesso e materiais semelhantes | I367: =VLOOKUP(D367,Base!$D:$F,3,FALSE) -> Fabricação de artefatos de concreto, cimento, fibrocimento, gesso e materiais semelhantes | J367: =VLOOKUP(E367,Base!$E:$F,2,FALSE) -> Fabricação de estruturas pré-moldadas de concreto armado, em série e sob encomenda | K367: 2330301 | L367: =IFERROR(VLOOKUP($K367,Base_Atividades!$E$1:$N$2398,MATCH(BancoAjustado!L$1,Base_Atividades!$E$1:$N$1,0),FALSE),0) -> 0 | M367: =IFERROR(VLOOKUP($K367,Base_Atividades!$E$1:$N$2398,MATCH(BancoAjustado!M$1,Base_Atividades!$E$1:$N$1,0),FALSE),0) -> 0 | N367: =IFERROR(VLOOKUP($K367,Base_Atividades!$E$1:$N$2398,MATCH(BancoAjustado!N$1,Base_Atividades!$E$1:$N$1,0),FALSE),0) -> 0
A368: C | B368: 23 | C368: 233 | D368: 23303 | E368: 2330302 | F368: =VLOOKUP(A368,Base!$A:$F,6,FALSE) -> INDÚSTRIAS DE TRANSFORMAÇÃO | G368: =VLOOKUP(B368,Base!$B:$F,5,FALSE) -> FABRICAÇÃO DE PRODUTOS DE MINERAIS NÃO METÁLICOS | H368: =VLOOKUP(C368,Base!$C:$F,4,FALSE) -> Fabricação de artefatos de concreto, cimento, fibrocimento, gesso e materiais semelhantes | I368: =VLOOKUP(D368,Base!$D:$F,3,FALSE) -> Fabricação de artefatos de concreto, cimento, fibrocimento, gesso e materiais semelhantes | J368: =VLOOKUP(E368,Base!$E:$F,2,FALSE) -> Fabricação de artefatos de cimento para uso na construção | K368: 2330302 | L368: =IFERROR(VLOOKUP($K368,Base_Atividades!$E$1:$N$2398,MATCH(BancoAjustado!L$1,Base_Atividades!$E$1:$N$1,0),FALSE),0) -> 0 | M368: =IFERROR(VLOOKUP($K368,Base_Atividades!$E$1:$N$2398,MATCH(BancoAjustado!M$1,Base_Atividades!$E$1:$N$1,0),FALSE),0) -> 0 | N368: =IFERROR(VLOOKUP($K368,Base_Atividades!$E$1:$N$2398,MATCH(BancoAjustado!N$1,Base_Atividades!$E$1:$N$1,0),FALSE),0) -> 0
A369: C | B369: 23 | C369: 233 | D369: 23303 | E369: 2330303 | F369: =VLOOKUP(A369,Base!$A:$F,6,FALSE) -> INDÚSTRIAS DE TRANSFORMAÇÃO | G369: =VLOOKUP(B369,Base!$B:$F,5,FALSE) -> FABRICAÇÃO DE PRODUTOS DE MINERAIS NÃO METÁLICOS | H369: =VLOOKUP(C369,Base!$C:$F,4,FALSE) -> Fabricação de artefatos de concreto, cimento, fibrocimento, gesso e materiais semelhantes | I369: =VLOOKUP(D369,Base!$D:$F,3,FALSE) -> Fabricação de artefatos de concreto, cimento, fibrocimento, gesso e materiais semelhantes | J369: =VLOOKUP(E369,Base!$E:$F,2,FALSE) -> Fabricação de artefatos de fibrocimento para uso na construção | K369: 2330303 | L369: =IFERROR(VLOOKUP($K369,Base_Atividades!$E$1:$N$2398,MATCH(BancoAjustado!L$1,Base_Atividades!$E$1:$N$1,0),FALSE),0) -> 0 | M369: =IFERROR(VLOOKUP($K369,Base_Atividades!$E$1:$N$2398,MATCH(BancoAjustado!M$1,Base_Atividades!$E$1:$N$1,0),FALSE),0) -> 0 | N369: =IFERROR(VLOOKUP($K369,Base_Atividades!$E$1:$N$2398,MATCH(BancoAjustado!N$1,Base_Atividades!$E$1:$N$1,0),FALSE),0) -> 0
A370: C | B370: 23 | C370: 233 | D370: 23303 | E370: 2330304 | F370: =VLOOKUP(A370,Base!$A:$F,6,FALSE) -> INDÚSTRIAS DE TRANSFORMAÇÃO | G370: =VLOOKUP(B370,Base!$B:$F,5,FALSE) -> FABRICAÇÃO DE PRODUTOS DE MINERAIS NÃO METÁLICOS | H370: =VLOOKUP(C370,Base!$C:$F,4,FALSE) -> Fabricação de artefatos de concreto, cimento, fibrocimento, gesso e materiais semelhantes | I370: =VLOOKUP(D370,Base!$D:$F,3,FALSE) -> Fabricação de artefatos de concreto, cimento, fibrocimento, gesso e materiais semelhantes | J370: =VLOOKUP(E370,Base!$E:$F,2,FALSE) -> Fabricação de casas pré-moldadas de concreto | K370: 2330304 | L370: =IFERROR(VLOOKUP($K370,Base_Atividades!$E$1:$N$2398,MATCH(BancoAjustado!L$1,Base_Atividades!$E$1:$N$1,0),FALSE),0) -> 0 | M370: =IFERROR(VLOOKUP($K370,Base_Atividades!$E$1:$N$2398,MATCH(BancoAjustado!M$1,Base_Atividades!$E$1:$N$1,0),FALSE),0) -> 0 | N370: =IFERROR(VLOOKUP($K370,Base_Atividades!$E$1:$N$2398,MATCH(BancoAjustado!N$1,Base_Atividades!$E$1:$N$1,0),FALSE),0) -> 0
A371: C | B371: 23 | C371: 233 | D371: 23303 | E371: 2330305 | F371: =VLOOKUP(A371,Base!$A:$F,6,FALSE) -> INDÚSTRIAS DE TRANSFORMAÇÃO | G371: =VLOOKUP(B371,Base!$B:$F,5,FALSE) -> FABRICAÇÃO DE PRODUTOS DE MINERAIS NÃO METÁLICOS | H371: =VLOOKUP(C371,Base!$C:$F,4,FALSE) -> Fabricação de artefatos de concreto, cimento, fibrocimento, gesso e materiais semelhantes | I371: =VLOOKUP(D371,Base!$D:$F,3,FALSE) -> Fabricação de artefatos de concreto, cimento, fibrocimento, gesso e materiais semelhantes | J371: =VLOOKUP(E371,Base!$E:$F,2,FALSE) -> Preparação de massa de concreto e argamassa para construção | K371: 2330305 | L371: =IFERROR(VLOOKUP($K371,Base_Atividades!$E$1:$N$2398,MATCH(BancoAjustado!L$1,Base_Atividades!$E$1:$N$1,0),FALSE),0) -> 0 | M371: =IFERROR(VLOOKUP($K371,Base_Atividades!$E$1:$N$2398,MATCH(BancoAjustado!M$1,Base_Atividades!$E$1:$N$1,0),FALSE),0) -> 0 | N371: =IFERROR(VLOOKUP($K371,Base_Atividades!$E$1:$N$2398,MATCH(BancoAjustado!N$1,Base_Atividades!$E$1:$N$1,0),FALSE),0) -> 0
A372: C | B372: 23 | C372: 233 | D372: 23303 | E372: 2330399 | F372: =VLOOKUP(A372,Base!$A:$F,6,FALSE) -> INDÚSTRIAS DE TRANSFORMAÇÃO | G372: =VLOOKUP(B372,Base!$B:$F,5,FALSE) -> FABRICAÇÃO DE PRODUTOS DE MINERAIS NÃO METÁLICOS | H372: =VLOOKUP(C372,Base!$C:$F,4,FALSE) -> Fabricação de artefatos de concreto, cimento, fibrocimento, gesso e materiais semelhantes | I372: =VLOOKUP(D372,Base!$D:$F,3,FALSE) -> Fabricação de artefatos de concreto, cimento, fibrocimento, gesso e materiais semelhantes | J372: =VLOOKUP(E372,Base!$E:$F,2,FALSE) -> Fabricação de outros artefatos e produtos de concreto, cimento, fibrocimento, gesso e materiais semelhantes | K372: 2330399 | L372: =IFERROR(VLOOKUP($K372,Base_Atividades!$E$1:$N$2398,MATCH(BancoAjustado!L$1,Base_Atividades!$E$1:$N$1,0),FALSE),0) -> 0 | M372: =IFERROR(VLOOKUP($K372,Base_Atividades!$E$1:$N$2398,MATCH(BancoAjustado!M$1,Base_Atividades!$E$1:$N$1,0),FALSE),0) -> 0 | N372: =IFERROR(VLOOKUP($K372,Base_Atividades!$E$1:$N$2398,MATCH(BancoAjustado!N$1,Base_Atividades!$E$1:$N$1,0),FALSE),0) -> 0
...

Sheet Base
A1: Seção | B1: Divisão | C1: Grupo | D1: Classe | E1: Subclasse | F1: Denominação
A2: A | F2: AGRICULTURA, PECUÁRIA, PRODUÇÃO FLORESTAL, PESCA E AQUICULTURA
B3: 01 | F3: AGRICULTURA, PECUÁRIA E SERVIÇOS RELACIONADOS
C4: 011 | F4: Produção de lavouras temporárias
D5: 01113 | F5: Cultivo de cereais
E6: 0111301 | F6: Cultivo de arroz | G6: =A2 -> A | H6: =B3 -> 01 | I6: =C4 -> 011 | J6: =D5 -> 01113 | K6: =E6 -> 0111301
E7: 0111302 | F7: Cultivo de milho | G7: =IF(A7="",G6,A7) -> A | H7: =IF(B7="",H6,B7) -> 01 | I7: =IF(C7="",I6,C7) -> 011 | J7: =IF(D7="",J6,D7) -> 01113 | K7: =E7 -> 0111302
E8: 0111303 | F8: Cultivo de trigo | G8: =IF(A8="",G7,A8) -> A | H8: =IF(B8="",H7,B8) -> 01 | I8: =IF(C8="",I7,C8) -> 011 | J8: =IF(D8="",J7,D8) -> 01113 | K8: =E8 -> 0111303
E9: 0111399 | F9: Cultivo de outros cereais não especificados anteriormente | G9: =IF(A9="",G8,A9) -> A | H9: =IF(B9="",H8,B9) -> 01 | I9: =IF(C9="",I8,C9) -> 011 | J9: =IF(D9="",J8,D9) -> 01113 | K9: =E9 -> 0111399
D10: 01121 | F10: Cultivo de algodão herbáceo e de outras fibras de lavoura temporária | G10: =IF(A10="",G9,A10) -> A | H10: =IF(B10="",H9,B10) -> 01 | I10: =IF(C10="",I9,C10) -> 011 | J10: =IF(D10="",J9,D10) -> 01121 | K10: =E10
E11: 0112101 | F11: Cultivo de algodão herbáceo | G11: =IF(A11="",G10,A11) -> A | H11: =IF(B11="",H10,B11) -> 01 | I11: =IF(C11="",I10,C11) -> 011 | J11: =IF(D11="",J10,D11) -> 01121 | K11: =E11 -> 0112101
E12: 0112102 | F12: Cultivo de juta | G12: =IF(A12="",G11,A12) -> A | H12: =IF(B12="",H11,B12) -> 01 | I12: =IF(C12="",I11,C12) -> 011 | J12: =IF(D12="",J11,D12) -> 01121 | K12: =E12 -> 0112102
E13: 0112199 | F13: Cultivo de outras fibras de lavoura temporária não especificadas anteriormente | G13: =IF(A13="",G12,A13) -> A | H13: =IF(B13="",H12,B13) -> 01 | I13: =IF(C13="",I12,C13) -> 011 | J13: =IF(D13="",J12,D13) -> 01121 | K13: =E13 -> 0112199
D14: 01130 | F14: Cultivo de cana-de-açúcar | G14: =IF(A14="",G13,A14) -> A | H14: =IF(B14="",H13,B14) -> 01 | I14: =IF(C14="",I13,C14) -> 011 | J14: =IF(D14="",J13,D14) -> 01130 | K14: =E14
E15: 0113000 | F15: Cultivo de cana-de-açúcar | G15: =IF(A15="",G14,A15) -> A | H15: =IF(B15="",H14,B15) -> 01 | I15: =IF(C15="",I14,C15) -> 011 | J15: =IF(D15="",J14,D15) -> 01130 | K15: =E15 -> 0113000
D16: 01148 | F16: Cultivo de fumo | G16: =IF(A16="",G15,A16) -> A | H16: =IF(B16="",H15,B16) -> 01 | I16: =IF(C16="",I15,C16) -> 011 | J16: =IF(D16="",J15,D16) -> 01148 | K16: =E16
E17: 0114800 | F17: Cultivo de fumo | G17: =IF(A17="",G16,A17) -> A | H17: =IF(B17="",H16,B17) -> 01 | I17: =IF(C17="",I16,C17) -> 011 | J17: =IF(D17="",J16,D17) -> 01148 | K17: =E17 -> 0114800
D18: 01156 | F18: Cultivo de soja | G18: =IF(A18="",G17,A18) -> A | H18: =IF(B18="",H17,B18) -> 01 | I18: =IF(C18="",I17,C18) -> 011 | J18: =IF(D18="",J17,D18) -> 01156 | K18: =E18
E19: 0115600 | F19: Cultivo de soja | G19: =IF(A19="",G18,A19) -> A | H19: =IF(B19="",H18,B19) -> 01 | I19: =IF(C19="",I18,C19) -> 011 | J19: =IF(D19="",J18,D19) -> 01156 | K19: =E19 -> 0115600
D20: 01164 | F20: Cultivo de oleaginosas de lavoura temporária, exceto soja | G20: =IF(A20="",G19,A20) -> A | H20: =IF(B20="",H19,B20) -> 01 | I20: =IF(C20="",I19,C20) -> 011 | J20: =IF(D20="",J19,D20) -> 01164 | K20: =E20
E21: 0116401 | F21: Cultivo de amendoim | G21: =IF(A21="",G20,A21) -> A | H21: =IF(B21="",H20,B21) -> 01 | I21: =IF(C21="",I20,C21) -> 011 | J21: =IF(D21="",J20,D21) -> 01164 | K21: =E21 -> 0116401
E22: 0116402 | F22: Cultivo de girassol | G22: =IF(A22="",G21,A22) -> A | H22: =IF(B22="",H21,B22) -> 01 | I22: =IF(C22="",I21,C22) -> 011 | J22: =IF(D22="",J21,D22) -> 01164 | K22: =E22 -> 0116402
E23: 0116403 | F23: Cultivo de mamona | G23: =IF(A23="",G22,A23) -> A | H23: =IF(B23="",H22,B23) -> 01 | I23: =IF(C23="",I22,C23) -> 011 | J23: =IF(D23="",J22,D23) -> 01164 | K23: =E23 -> 0116403
E24: 0116499 | F24: Cultivo de outras oleaginosas de lavoura temporária não especificadas anteriormente | G24: =IF(A24="",G23,A24) -> A | H24: =IF(B24="",H23,B24) -> 01 | I24: =IF(C24="",I23,C24) -> 011 | J24: =IF(D24="",J23,D24) -> 01164 | K24: =E24 -> 0116499
D25: 01199 | F25: Cultivo de plantas de lavoura temporária não especificadas anteriormente | G25: =IF(A25="",G24,A25) -> A | H25: =IF(B25="",H24,B25) -> 01 | I25: =IF(C25="",I24,C25) -> 011 | J25: =IF(D25="",J24,D25) -> 01199 | K25: =E25
E26: 0119901 | F26: Cultivo de abacaxi | G26: =IF(A26="",G25,A26) -> A | H26: =IF(B26="",H25,B26) -> 01 | I26: =IF(C26="",I25,C26) -> 011 | J26: =IF(D26="",J25,D26) -> 01199 | K26: =E26 -> 0119901
E27: 0119902 | F27: Cultivo de alho | G27: =IF(A27="",G26,A27) -> A | H27: =IF(B27="",H26,B27) -> 01 | I27: =IF(C27="",I26,C27) -> 011 | J27: =IF(D27="",J26,D27) -> 01199 | K27: =E27 -> 0119902
E28: 0119903 | F28: Cultivo de batata-inglesa | G28: =IF(A28="",G27,A28) -> A | H28: =IF(B28="",H27,B28) -> 01 | I28: =IF(C28="",I27,C28) -> 011 | J28: =IF(D28="",J27,D28) -> 01199 | K28: =E28 -> 0119903
E29: 0119904 | F29: Cultivo de cebola | G29: =IF(A29="",G28,A29) -> A | H29: =IF(B29="",H28,B29) -> 01 | I29: =IF(C29="",I28,C29) -> 011 | J29: =IF(D29="",J28,D29) -> 01199 | K29: =E29 -> 0119904
E30: 0119905 | F30: Cultivo de feijão | G30: =IF(A30="",G29,A30) -> A | H30: =IF(B30="",H29,B30) -> 01 | I30: =IF(C30="",I29,C30) -> 011 | J30: =IF(D30="",J29,D30) -> 01199 | K30: =E30 -> 0119905
E31: 0119906 | F31: Cultivo de mandioca | G31: =IF(A31="",G30,A31) -> A | H31: =IF(B31="",H30,B31) -> 01 | I31: =IF(C31="",I30,C31) -> 011 | J31: =IF(D31="",J30,D31) -> 01199 | K31: =E31 -> 0119906
E32: 0119907 | F32: Cultivo de melão | G32: =IF(A32="",G31,A32) -> A | H32: =IF(B32="",H31,B32) -> 01 | I32: =IF(C32="",I31,C32) -> 011 | J32: =IF(D32="",J31,D32) -> 01199 | K32: =E32 -> 0119907
E33: 0119908 | F33: Cultivo de melancia | G33: =IF(A33="",G32,A33) -> A | H33: =IF(B33="",H32,B33) -> 01 | I33: =IF(C33="",I32,C33) -> 011 | J33: =IF(D33="",J32,D33) -> 01199 | K33: =E33 -> 0119908
E34: 0119909 | F34: Cultivo de tomate rasteiro | G34: =IF(A34="",G33,A34) -> A | H34: =IF(B34="",H33,B34) -> 01 | I34: =IF(C34="",I33,C34) -> 011 | J34: =IF(D34="",J33,D34) -> 01199 | K34: =E34 -> 0119909
E35: 0119999 | F35: Cultivo de outras plantas de lavoura temporária não especificadas anteriormente | G35: =IF(A35="",G34,A35) -> A | H35: =IF(B35="",H34,B35) -> 01 | I35: =IF(C35="",I34,C35) -> 011 | J35: =IF(D35="",J34,D35) -> 01199 | K35: =E35 -> 0119999
C36: 012 | F36: Horticultura e floricultura | G36: =IF(A36="",G35,A36) -> A | H36: =IF(B36="",H35,B36) -> 01 | I36: =IF(C36="",I35,C36) -> 012 | J36: =IF(D36="",J35,D36) -> 01199 | K36: =E36
D37: 01211 | F37: Horticultura | G37: =IF(A37="",G36,A37) -> A | H37: =IF(B37="",H36,B37) -> 01 | I37: =IF(C37="",I36,C37) -> 012 | J37: =IF(D37="",J36,D37) -> 01211 | K37: =E37
E38: 0121101 | F38: Horticultura, exceto morango | G38: =IF(A38="",G37,A38) -> A | H38: =IF(B38="",H37,B38) -> 01 | I38: =IF(C38="",I37,C38) -> 012 | J38: =IF(D38="",J37,D38) -> 01211 | K38: =E38 -> 0121101
E39: 0121102 | F39: Cultivo de morango | G39: =IF(A39="",G38,A39) -> A | H39: =IF(B39="",H38,B39) -> 01 | I39: =IF(C39="",I38,C39) -> 012 | J39: =IF(D39="",J38,D39) -> 01211 | K39: =E39 -> 0121102
D40: 01229 | F40: Cultivo de flores e plantas ornamentais | G40: =IF(A40="",G39,A40) -> A | H40: =IF(B40="",H39,B40) -> 01 | I40: =IF(C40="",I39,C40) -> 012 | J40: =IF(D40="",J39,D40) -> 01229 | K40: =E40
...

Sheet Base_Atividades
A1: Seção | B1: Divisão | C1: Grupo | D1: Classe | E1: Subclasse | F1: Denominação | L1: e_obj4 | M1: com_agr | N1: com_min
A2: A | F2: AGRICULTURA, PECUÁRIA, PRODUÇÃO FLORESTAL, PESCA E AQUICULTURA
B3: 01 | F3: AGRICULTURA, PECUÁRIA E SERVIÇOS RELACIONADOS
C4: 011 | F4: Produção de lavouras temporárias
D5: 01113 | F5: Cultivo de cereais
E6: 0111301 | F6: Cultivo de arroz | G6: =A2 -> A | H6: =B3 -> 01 | I6: =C4 -> 011 | J6: =D5 -> 01113 | K6: =E6 -> 0111301 | L6: 1
E7: 0111302 | F7: Cultivo de milho | G7: =IF(A7="",G6,A7) -> A | H7: =IF(B7="",H6,B7) -> 01 | I7: =IF(C7="",I6,C7) -> 011 | J7: =IF(D7="",J6,D7) -> 01113 | K7: =E7 -> 0111302 | L7: 0 | M7: 1
E8: 0111303 | F8: Cultivo de trigo | G8: =IF(A8="",G7,A8) -> A | H8: =IF(B8="",H7,B8) -> 01 | I8: =IF(C8="",I7,C8) -> 011 | J8: =IF(D8="",J7,D8) -> 01113 | K8: =E8 -> 0111303 | L8: 0 | M8: 1
E9: 0111399 | F9: Cultivo de outros cereais não especificados anteriormente | G9: =IF(A9="",G8,A9) -> A | H9: =IF(B9="",H8,B9) -> 01 | I9: =IF(C9="",I8,C9) -> 011 | J9: =IF(D9="",J8,D9) -> 01113 | K9: =E9 -> 0111399 | L9: 1
D10: 01121 | F10: Cultivo de algodão herbáceo e de outras fibras de lavoura temporária | G10: =IF(A10="",G9,A10) -> A | H10: =IF(B10="",H9,B10) -> 01 | I10: =IF(C10="",I9,C10) -> 011 | J10: =IF(D10="",J9,D10) -> 01121 | K10: =E10
E11: 0112101 | F11: Cultivo de algodão herbáceo | G11: =IF(A11="",G10,A11) -> A | H11: =IF(B11="",H10,B11) -> 01 | I11: =IF(C11="",I10,C11) -> 011 | J11: =IF(D11="",J10,D11) -> 01121 | K11: =E11 -> 0112101 | L11: 0 | M11: 1
E12: 0112102 | F12: Cultivo de juta | G12: =IF(A12="",G11,A12) -> A | H12: =IF(B12="",H11,B12) -> 01 | I12: =IF(C12="",I11,C12) -> 011 | J12: =IF(D12="",J11,D12) -> 01121 | K12: =E12 -> 0112102 | L12: 1
E13: 0112199 | F13: Cultivo de outras fibras de lavoura temporária não especificadas anteriormente | G13: =IF(A13="",G12,A13) -> A | H13: =IF(B13="",H12,B13) -> 01 | I13: =IF(C13="",I12,C13) -> 011 | J13: =IF(D13="",J12,D13) -> 01121 | K13: =E13 -> 0112199 | L13: 1
D14: 01130 | F14: Cultivo de cana-de-açúcar | G14: =IF(A14="",G13,A14) -> A | H14: =IF(B14="",H13,B14) -> 01 | I14: =IF(C14="",I13,C14) -> 011 | J14: =IF(D14="",J13,D14) -> 01130 | K14: =E14
E15: 0113000 | F15: Cultivo de cana-de-açúcar | G15: =IF(A15="",G14,A15) -> A | H15: =IF(B15="",H14,B15) -> 01 | I15: =IF(C15="",I14,C15) -> 011 | J15: =IF(D15="",J14,D15) -> 01130 | K15: =E15 -> 0113000 | L15: 0 | M15: 1
D16: 01148 | F16: Cultivo de fumo | G16: =IF(A16="",G15,A16) -> A | H16: =IF(B16="",H15,B16) -> 01 | I16: =IF(C16="",I15,C16) -> 011 | J16: =IF(D16="",J15,D16) -> 01148 | K16: =E16
E17: 0114800 | F17: Cultivo de fumo | G17: =IF(A17="",G16,A17) -> A | H17: =IF(B17="",H16,B17) -> 01 | I17: =IF(C17="",I16,C17) -> 011 | J17: =IF(D17="",J16,D17) -> 01148 | K17: =E17 -> 0114800 | L17: 0
D18: 01156 | F18: Cultivo de soja | G18: =IF(A18="",G17,A18) -> A | H18: =IF(B18="",H17,B18) -> 01 | I18: =IF(C18="",I17,C18) -> 011 | J18: =IF(D18="",J17,D18) -> 01156 | K18: =E18
E19: 0115600 | F19: Cultivo de soja | G19: =IF(A19="",G18,A19) -> A | H19: =IF(B19="",H18,B19) -> 01 | I19: =IF(C19="",I18,C19) -> 011 | J19: =IF(D19="",J18,D19) -> 01156 | K19: =E19 -> 0115600 | L19: 0 | M19: 1
D20: 01164 | F20: Cultivo de oleaginosas de lavoura temporária, exceto soja | G20: =IF(A20="",G19,A20) -> A | H20: =IF(B20="",H19,B20) -> 01 | I20: =IF(C20="",I19,C20) -> 011 | J20: =IF(D20="",J19,D20) -> 01164 | K20: =E20
E21: 0116401 | F21: Cultivo de amendoim | G21: =IF(A21="",G20,A21) -> A | H21: =IF(B21="",H20,B21) -> 01 | I21: =IF(C21="",I20,C21) -> 011 | J21: =IF(D21="",J20,D21) -> 01164 | K21: =E21 -> 0116401 | L21: 1
E22: 0116402 | F22: Cultivo de girassol | G22: =IF(A22="",G21,A22) -> A | H22: =IF(B22="",H21,B22) -> 01 | I22: =IF(C22="",I21,C22) -> 011 | J22: =IF(D22="",J21,D22) -> 01164 | K22: =E22 -> 0116402 | L22: 1
E23: 0116403 | F23: Cultivo de mamona | G23: =IF(A23="",G22,A23) -> A | H23: =IF(B23="",H22,B23) -> 01 | I23: =IF(C23="",I22,C23) -> 011 | J23: =IF(D23="",J22,D23) -> 01164 | K23: =E23 -> 0116403 | L23: 1
E24: 0116499 | F24: Cultivo de outras oleaginosas de lavoura temporária não especificadas anteriormente | G24: =IF(A24="",G23,A24) -> A | H24: =IF(B24="",H23,B24) -> 01 | I24: =IF(C24="",I23,C24) -> 011 | J24: =IF(D24="",J23,D24) -> 01164 | K24: =E24 -> 0116499 | L24: 1
D25: 01199 | F25: Cultivo de plantas de lavoura temporária não especificadas anteriormente | G25: =IF(A25="",G24,A25) -> A | H25: =IF(B25="",H24,B25) -> 01 | I25: =IF(C25="",I24,C25) -> 011 | J25: =IF(D25="",J24,D25) -> 01199 | K25: =E25
E26: 0119901 | F26: Cultivo de abacaxi | G26: =IF(A26="",G25,A26) -> A | H26: =IF(B26="",H25,B26) -> 01 | I26: =IF(C26="",I25,C26) -> 011 | J26: =IF(D26="",J25,D26) -> 01199 | K26: =E26 -> 0119901 | L26: 1
E27: 0119902 | F27: Cultivo de alho | G27: =IF(A27="",G26,A27) -> A | H27: =IF(B27="",H26,B27) -> 01 | I27: =IF(C27="",I26,C27) -> 011 | J27: =IF(D27="",J26,D27) -> 01199 | K27: =E27 -> 0119902 | L27: 1
E28: 0119903 | F28: Cultivo de batata-inglesa | G28: =IF(A28="",G27,A28) -> A | H28: =IF(B28="",H27,B28) -> 01 | I28: =IF(C28="",I27,C28) -> 011 | J28: =IF(D28="",J27,D28) -> 01199 | K28: =E28 -> 0119903 | L28: 1
E29: 0119904 | F29: Cultivo de cebola | G29: =IF(A29="",G28,A29) -> A | H29: =IF(B29="",H28,B29) -> 01 | I29: =IF(C29="",I28,C29) -> 011 | J29: =IF(D29="",J28,D29) -> 01199 | K29: =E29 -> 0119904 | L29: 1
E30: 0119905 | F30: Cultivo de feijão | G30: =IF(A30="",G29,A30) -> A | H30: =IF(B30="",H29,B30) -> 01 | I30: =IF(C30="",I29,C30) -> 011 | J30: =IF(D30="",J29,D30) -> 01199 | K30: =E30 -> 0119905 | L30: 1
E31: 0119906 | F31: Cultivo de mandioca | G31: =IF(A31="",G30,A31) -> A | H31: =IF(B31="",H30,B31) -> 01 | I31: =IF(C31="",I30,C31) -> 011 | J31: =IF(D31="",J30,D31) -> 01199 | K31: =E31 -> 0119906 | L31: 1
E32: 0119907 | F32: Cultivo de melão | G32: =IF(A32="",G31,A32) -> A | H32: =IF(B32="",H31,B32) -> 01 | I32: =IF(C32="",I31,C32) -> 011 | J32: =IF(D32="",J31,D32) -> 01199 | K32: =E32 -> 0119907 | L32: 1
E33: 0119908 | F33: Cultivo de melancia | G33: =IF(A33="",G32,A33) -> A | H33: =IF(B33="",H32,B33) -> 01 | I33: =IF(C33="",I32,C33) -> 011 | J33: =IF(D33="",J32,D33) -> 01199 | K33: =E33 -> 0119908 | L33: 1
E34: 0119909 | F34: Cultivo de tomate rasteiro | G34: =IF(A34="",G33,A34) -> A | H34: =IF(B34="",H33,B34) -> 01 | I34: =IF(C34="",I33,C34) -> 011 | J34: =IF(D34="",J33,D34) -> 01199 | K34: =E34 -> 0119909 | L34: 1
E35: 0119999 | F35: Cultivo de outras plantas de lavoura temporária não especificadas anteriormente | G35: =IF(A35="",G34,A35) -> A | H35: =IF(B35="",H34,B35) -> 01 | I35: =IF(C35="",I34,C35) -> 011 | J35: =IF(D35="",J34,D35) -> 01199 | K35: =E35 -> 0119999 | L35: 1
C36: 012 | F36: Horticultura e floricultura | G36: =IF(A36="",G35,A36) -> A | H36: =IF(B36="",H35,B36) -> 01 | I36: =IF(C36="",I35,C36) -> 012 | J36: =IF(D36="",J35,D36) -> 01199 | K36: =E36
D37: 01211 | F37: Horticultura | G37: =IF(A37="",G36,A37) -> A | H37: =IF(B37="",H36,B37) -> 01 | I37: =IF(C37="",I36,C37) -> 012 | J37: =IF(D37="",J36,D37) -> 01211 | K37: =E37
E38: 0121101 | F38: Horticultura, exceto morango | G38: =IF(A38="",G37,A38) -> A | H38: =IF(B38="",H37,B38) -> 01 | I38: =IF(C38="",I37,C38) -> 012 | J38: =IF(D38="",J37,D38) -> 01211 | K38: =E38 -> 0121101 | L38: 1
E39: 0121102 | F39: Cultivo de morango | G39: =IF(A39="",G38,A39) -> A | H39: =IF(B39="",H38,B39) -> 01 | I39: =IF(C39="",I38,C39) -> 012 | J39: =IF(D39="",J38,D39) -> 01211 | K39: =E39 -> 0121102 | L39: 1
D40: 01229 | F40: Cultivo de flores e plantas ornamentais | G40: =IF(A40="",G39,A40) -> A | H40: =IF(B40="",H39,B40) -> 01 | I40: =IF(C40="",I39,C40) -> 012 | J40: =IF(D40="",J39,D40) -> 01229 | K40: =E40
...
